Workbook

Sheet Reorg Summary
A1: PMS Questionnaire Reorganization – Executive & KPI Focus
A2: The active catalogue retains simple/direct questions with tags, replaces recoverable empty-table dependencies, defers unsupported modules, and adds high-value executive/KPI questions based on populated tables.
A5: Metric | B5: Count | D5: Complexity | E5: Count
A6: Active questionnaire questions | B6: =COUNTA('Reorganized Questionnaire'!I:I)-1 | D6: Simple | E6: =COUNTIF('Reorganized Questionnaire'!G:G,"Simple")
A7: Retained or reworked existing questions | B7: =COUNTIF('Reorganized Questionnaire'!A:A,"Existing*") | D7: Moderate | E7: =COUNTIF('Reorganized Questionnaire'!G:G,"Moderate")
A8: New executive/KPI questions | B8: =COUNTIF('Reorganized Questionnaire'!A:A,"New*") | D8: Complex | E8: =COUNTIF('Reorganized Questionnaire'!G:G,"Complex")
A9: Deferred due to empty tables | B9: =COUNTA('Deferred Empty Tables'!A:A)-1 | D9: Very Complex | E9: =COUNTIF('Reorganized Questionnaire'!G:G,"Very Complex")
A10: High executive-priority questions | B10: =COUNTIF('Reorganized Questionnaire'!D:D,"High")
A11: High LLM-error-risk questions | B11: =COUNTIF('Reorganized Questionnaire'!R:R,"High")
A14: Implementation principle
A15: • Simple questions: use FAQ Tool Call Binding and parameterized SQL; execute against live data.
A16: • Complex KPI questions: implement fixed formulas and joins in an Orbit KPI/Watchlist Tool. Do not let the LLM invent calculations.
A17: • Mesh can explain, compare, and narrate results only after the governed tool computes the metrics.
A18: • Questions depending on empty milestone, estimation, or team tables remain deferred until data is populated.

Sheet Reorganized Questionnaire
A1: Source | B1: Original ID | C1: Audience | D1: Executive Priority | E1: PMS Area | F1: Question Type | G1: Complexity Tag | H1: Canonical Intent | I1: Primary Question | J1: Alternative Phrasing 1 | K1: Alternative Phrasing 2 | L1: Required Parameters | M1: Business Decision / Value | N1: KPI / Derivation Logic | O1: Relevant Populated Tables | P1: Data Readiness | Q1: Query Strategy | R1: LLM Error Risk | S1: Recommended Execution / Cache | T1: Query Mapping Status | U1: SQL Query (Existing or Recovered) | V1: Notes
A2: Existing – Retained | B2: 1 | C2: Portfolio Head / Delivery Manager / PM | D2: Low | E2: Projects | F2: Simple Lookup / Filter | G2: Simple | H2: my_active_projects | I2: What are my active projects? | J2: Show the projects I am currently working on. | K2: List my ongoing projects. | L2: current_user | M2: Fast operational lookup and drill-down. | N2: Direct lookup/filter; no derived KPI. | O2: tbl_projects; tbl_project_users | P2: N/A | Q2: Parameterized lookup/filter | R2: Low | S2: FAQ Tool Call Binding + parameterized SQL; cache intent/SQL, not live response | T2: Not Mapped – Business Rule Required | U2: SELECT DISTINCT p.project_id, p.project_unique_id, p.project_key, p.title, p.start_date, p.end_date, ps.status_name, st.stage_name, p.priority, p.rag FROM tbl_projects p JOIN tbl_project_users pu ON p.project_id = pu.project_id LEFT JOIN tbl_project_status ps ON ps.status_id = p.project_status_id LEFT JOIN tbl_project_stages st ON st.stage_id = p.project_stage_id WHERE pu.user_id = 3066 AND pu.request_status = 'A' AND pu.status = 1 AND p.status = 1 AND p.archive = 0 ORDER BY p.title ASC | V2: Define whether “my” includes member, PM, owner, or task assignee.
A3: Existing – Retained | B3: 2 | C3: Portfolio Head / Delivery Manager / PM | D3: Low | E3: Projects | F3: Simple Lookup / Filter | G3: Simple | H3: projects_managed_by_me | I3: Which projects am I managing? | J3: Show projects where I am the project manager. | K3: List projects managed by me. | L3: current_user | M3: Fast operational lookup and drill-down. | N3: Direct lookup/filter; no derived KPI. | O3: tbl_projects.pm_user_id | P3: Data Available | Q3: Parameterized lookup/filter | R3: Low | S3: FAQ Tool Call Binding + parameterized SQL; cache intent/SQL, not live response | T3: Mapped – Direct Schema | U3: SELECT p.project_id, p.project_unique_id, p.project_key, p.title, p.start_date, p.end_date, ps.status_name, st.stage_name, p.priority, p.rag FROM tbl_projects p LEFT JOIN tbl_project_status ps ON ps.status_id = p.project_status_id LEFT JOIN tbl_project_stages st ON st.stage_id = p.project_stage_id WHERE p.pm_user_id = :current_user_id AND p.status = 1 AND p.archive = 0 ORDER BY p.end_date, p.title; | V3: Use PM field; confirm whether project_owner_id also counts.
A4: Existing – Retained | B4: 3 | C4: Portfolio Head / Delivery Manager / PM | D4: Low | E4: Projects | F4: Simple Lookup / Filter | G4: Simple | H4: projects_owned_by_me | I4: Which projects do I own? | J4: Show projects where I am the owner. | K4: List projects owned by me. | L4: current_user | M4: Fast operational lookup and drill-down. | N4: Direct lookup/filter; no derived KPI. | O4: tbl_projects.project_owner_id | P4: Data Available | Q4: Parameterized lookup/filter | R4: Low | S4: FAQ Tool Call Binding + parameterized SQL; cache intent/SQL, not live response | T4: Mapped – Direct Schema | U4: SELECT p.project_id, p.project_unique_id, p.project_key, p.title, p.start_date, p.end_date, ps.status_name, st.stage_name, p.priority, p.rag FROM tbl_projects p LEFT JOIN tbl_project_status ps ON ps.status_id = p.project_status_id LEFT JOIN tbl_project_stages st ON st.stage_id = p.project_stage_id WHERE p.project_owner_id = :current_user_id AND p.status = 1 AND p.archive = 0 ORDER BY p.end_date, p.title; | V4: Distinct from project manager.
A5: Existing – Retained | B5: 4 | C5: Portfolio Head / Delivery Manager / PM | D5: Medium | E5: Projects | F5: Simple Lookup / Filter | G5: Moderate | H5: project_details | I5: Show details of project :project_name. | J5: Give me the project information for :project_name. | K5: Open the summary of :project_name. | L5: project_name | M5: Fast operational lookup and drill-down. | N5: Direct lookup/filter; no derived KPI. | O5: tbl_projects | P5: N/A | Q5: Parameterized lookup/filter | R5: Medium | S5: FAQ/NL2SQL cached template or Orbit aggregation tool; execute on live data | T5: Not Mapped – Schema Ambiguous | V5: Project-name matching and duplicate-title handling required.
A6: Existing – Retained | B6: 5 | C6: Portfolio Head / Delivery Manager / PM | D6: Low | E6: Projects | F6: Simple Lookup / Filter | G6: Simple | H6: project_status | I6: What is the status of project :project_name? | J6: Show the current status of :project_name. | K6: Is :project_name active or completed? | L6: project_name | M6: Fast operational lookup and drill-down. | N6: Direct lookup/filter; no derived KPI. | O6: tbl_projects; tbl_project_status | P6: Data Available | Q6: Parameterized lookup/filter | R6: Low | S6: FAQ Tool Call Binding + parameterized SQL; cache intent/SQL, not live response | T6: Mapped – Direct Schema | U6: SELECT p.project_id, p.project_key, p.title, p.project_status_id, ps.status_name, ps.color_code FROM tbl_projects p LEFT JOIN tbl_project_status ps ON ps.status_id = p.project_status_id WHERE p.title = :project_name AND p.status = 1 AND p.archive = 0 ORDER BY p.project_id; | V6: Lookup master data required.
A7: Existing – Retained | B7: 6 | C7: Portfolio Head / Delivery Manager / PM | D7: Low | E7: Projects | F7: Simple Lookup / Filter | G7: Simple | H7: project_stage | I7: What stage is :project_name in? | J7: Show the current stage of :project_name. | K7: Which delivery stage has :project_name reached? | L7: project_name | M7: Fast operational lookup and drill-down. | N7: Direct lookup/filter; no derived KPI. | O7: tbl_projects; tbl_project_stages | P7: Data Available | Q7: Parameterized lookup/filter | R7: Low | S7: FAQ Tool Call Binding + parameterized SQL; cache intent/SQL, not live response | T7: Mapped – Direct Schema | U7: SELECT p.project_id, p.project_key, p.title, p.project_stage_id, st.stage_name, st.color_code FROM tbl_projects p LEFT JOIN tbl_project_stages st ON st.stage_id = p.project_stage_id WHERE p.title = :project_name AND p.status = 1 AND p.archive = 0 ORDER BY p.project_id; | V7: Lookup master data required.
A8: Existing – Retained | B8: 7 | C8: Portfolio Head / Delivery Manager / PM | D8: Low | E8: Projects | F8: Simple Lookup / Filter | G8: Simple | H8: project_rag | I8: What is the RAG status of :project_name? | J8: Show the health colour of :project_name. | K8: Is :project_name red, amber, or green? | L8: project_name | M8: Fast operational lookup and drill-down. | N8: Direct lookup/filter; no derived KPI. | O8: tbl_projects.rag | P8: Data Available | Q8: Parameterized lookup/filter | R8: Low | S8: FAQ Tool Call Binding + parameterized SQL; cache intent/SQL, not live response | T8: Mapped – Direct Schema | U8: SELECT p.project_id, p.project_key, p.title, p.rag FROM tbl_projects p WHERE p.title = :project_name AND p.status = 1 AND p.archive = 0 ORDER BY p.project_id; | V8: Confirm stored values and meaning.
A9: Existing – Reworked with Populated Alternative | B9: 8 | C9: Portfolio Head / Delivery Manager / PM | D9: Low | E9: Projects | F9: Simple Lookup / Filter | G9: Simple | H9: project_priority_code | I9: What priority code is stored for :project_name? | J9: Show the stored priority value for :project_name. | K9: What is the current project priority code for :project_name? | L9: project_name or project_unique_id | M9: Fast operational lookup and drill-down. | N9: Direct lookup/filter; no derived KPI. | O9: tbl_projects | P9: Available – Raw Code Only | Q9: Parameterized lookup/filter | R9: Low | S9: FAQ Tool Call Binding + parameterized SQL; cache intent/SQL, not live response | T9: Mapped – Populated Alternative | U9: SELECT p.project_id, p.project_unique_id, p.project_key, p.title, p.priority FROM tbl_projects p WHERE (p.project_unique_id = :project_identifier OR p.project_key = :project_identifier OR p.title = :project_identifier) AND p.status = 1 AND p.archive = 0 ORDER BY p.project_id; | V9: The lookup table tbl_project_priority is empty. The raw numeric value in tbl_projects.priority is available, but its business label must be confirmed. Recovered from empty-table dependency.
A10: Existing – Retained | B10: 9 | C10: Portfolio Head / Delivery Manager / PM | D10: Low | E10: Projects | F10: Simple Lookup / Filter | G10: Simple | H10: projects_starting_period | I10: Which projects start between :start_date and :end_date? | J10: Show projects beginning in the selected period. | K10: List upcoming project starts. | L10: start_date, end_date | M10: Fast operational lookup and drill-down. | N10: Direct lookup/filter; no derived KPI. | O10: tbl_projects.start_date | P10: Data Available | Q10: Parameterized lookup/filter | R10: Low | S10: FAQ Tool Call Binding + parameterized SQL; cache intent/SQL, not live response | T10: Mapped – Direct Schema | U10: SELECT p.project_id, p.project_key, p.title, p.start_date, p.end_date, ps.status_name, p.rag FROM tbl_projects p LEFT JOIN tbl_project_status ps ON ps.status_id = p.project_status_id WHERE p.start_date >= :start_date AND p.start_date < DATE_ADD(:end_date, INTERVAL 1 DAY) AND p.status = 1 AND p.archive = 0 ORDER BY p.start_date, p.title; | V10: Date boundaries to be inclusive.
A11: Existing – Retained | B11: 10 | C11: Portfolio Head / Delivery Manager / PM | D11: Low | E11: Projects | F11: Simple Lookup / Filter | G11: Simple | H11: projects_ending_period | I11: Which projects end between :start_date and :end_date? | J11: Show projects scheduled to finish in the selected period. | K11: List upcoming project end dates. | L11: start_date, end_date | M11: Fast operational lookup and drill-down. | N11: Direct lookup/filter; no derived KPI. | O11: tbl_projects.end_date | P11: Data Available | Q11: Parameterized lookup/filter | R11: Low | S11: FAQ Tool Call Binding + parameterized SQL; cache intent/SQL, not live response | T11: Mapped – Direct Schema | U11: SELECT p.project_id, p.project_key, p.title, p.start_date, p.end_date, ps.status_name, p.rag FROM tbl_projects p LEFT JOIN tbl_project_status ps ON ps.status_id = p.project_status_id WHERE p.end_date >= :start_date AND p.end_date < DATE_ADD(:end_date, INTERVAL 1 DAY) AND p.status = 1 AND p.archive = 0 ORDER BY p.end_date, p.title; | V11: Date boundaries to be inclusive.
A12: Existing – Retained | B12: 11 | C12: Portfolio Head / Delivery Manager / PM | D12: Medium | E12: Projects | F12: Exception / Diagnostic | G12: Complex | H12: overdue_projects | I12: Which projects are overdue? | J12: Show active projects past their end date. | K12: List delayed projects. | L12: as_of_date | M12: Identify exceptions requiring owner action. | N12: Define which project statuses are considered open. | O12: tbl_projects.end_date; tbl_project_status | P12: N/A | Q12: Exception query with joins and threshold filters | R12: High | S12: Orbit KPI Tool with predefined metric logic; Mesh may explain results but must not calculate metrics freely | T12: Not Applicable – Non-Direct Support | V12: Define which project statuses are considered open.
A13: Existing – Reworked with Populated Alternative | B13: 12 | C13: Portfolio Head / Delivery Manager / PM | D13: Low | E13: Projects | F13: Simple Lookup / Filter | G13: Simple | H13: projects_by_department | I13: Show active projects for department :department_name. | J13: Which active projects belong to :department_name? | K13: Give me the project portfolio for :department_name. | L13: department_name | M13: Fast operational lookup and drill-down. | N13: Direct lookup/filter; no derived KPI. | O13: tbl_projects; department | P13: Available – Alternative Table | Q13: Parameterized lookup/filter | R13: Low | S13: FAQ Tool Call Binding + parameterized SQL; cache intent/SQL, not live response | T13: Mapped – Populated Alternative | U13: SELECT p.project_id, p.project_unique_id, p.project_key, p.title, p.start_date, p.end_date, p.rag, d.name AS department_name FROM tbl_projects p JOIN department d ON d.group_id = p.department_id WHERE d.name = :department_name AND p.status = 1 AND p.archive = 0 ORDER BY p.end_date, p.title; | V13: Use populated department table instead of empty tbl_project_department. Confirm join tbl_projects.department_id = department.group_id. Recovered from empty-table dependency.
A14: Existing – Retained | B14: 14 | C14: Portfolio Head / Delivery Manager / PM | D14: Low | E14: Projects | F14: Simple Lookup / Filter | G14: Simple | H14: projects_by_type | I14: Show projects of type :project_type. | J14: List :project_type projects. | K14: Which projects use project type :project_type? | L14: project_type | M14: Fast operational lookup and drill-down. | N14: Direct lookup/filter; no derived KPI. | O14: tbl_projects.project_type_id; tbl_project_types | P14: Data Available | Q14: Parameterized lookup/filter | R14: Low | S14: FAQ Tool Call Binding + parameterized SQL; cache intent/SQL, not live response | T14: Mapped – Direct Schema | U14: SELECT p.project_id, p.project_key, p.title, pt.project_type, ps.status_name, p.start_date, p.end_date FROM tbl_projects p JOIN tbl_project_types pt ON pt.project_type_id = p.project_type_id LEFT JOIN tbl_project_status ps ON ps.status_id = p.project_status_id WHERE pt.project_type = :project_type AND p.status = 1 AND p.archive = 0 ORDER BY p.title; | V14: Lookup values required.
A15: Existing – Retained | B15: 15 | C15: Portfolio Head / Delivery Manager / PM | D15: Medium | E15: Projects | F15: Derived Analysis | G15: Very Complex | H15: projects_by_client | I15: Show projects for client :client_name. | J15: List projects associated with :client_name. | K15: Which projects belong to :client_name? | L15: client_name | M15: Support governed management analysis. | N15: Client master table must be confirmed. | O15: tbl_projects.client_id | P15: N/A | Q15: Governed multi-table query | R15: High | S15: Orbit KPI Tool with predefined metric logic; Mesh may explain results but must not calculate metrics freely | T15: Not Applicable – Non-Direct Support | V15: Client master table must be confirmed.
A16: Existing – Retained | B16: 16 | C16: Portfolio Head / Delivery Manager / PM | D16: High | E16: Projects | F16: Aggregation / Dashboard KPI | G16: Complex | H16: project_team_size | I16: How many active users are allocated to :project_name? | J16: Show the team size of :project_name. | K16: How many people are on :project_name? | L16: project_name | M16: Provide a reusable dashboard metric for monitoring. | N16: Define active allocation and request_status filters. | O16: tbl_project_users | P16: N/A | Q16: Predefined aggregation / grouped KPI query | R16: High | S16: Orbit KPI Tool with predefined metric logic; Mesh may explain results but must not calculate metrics freely | T16: Not Mapped – Business Rule Required | V16: Define active allocation and request_status filters.
A17: Existing – Retained | B17: 17 | C17: Portfolio Head / Delivery Manager / PM | D17: Medium | E17: Projects | F17: Exception / Diagnostic | G17: Moderate | H17: projects_without_pm | I17: Which projects do not have a project manager? | J17: Show projects with no PM assigned. | K17: List unowned PM assignments. | L17: none | M17: Identify exceptions requiring owner action. | N17: Null and zero handling required. | O17: tbl_projects.pm_user_id | P17: Data Available | Q17: Exception query with joins and threshold filters | R17: Medium | S17: FAQ/NL2SQL cached template or Orbit aggregation tool; execute on live data | T17: Mapped – Direct Schema | U17: SELECT p.project_id, p.project_key, p.title, p.start_date, p.end_date, ps.status_name FROM tbl_projects p LEFT JOIN tbl_project_status ps ON ps.status_id = p.project_status_id WHERE p.pm_user_id IS NULL AND p.status = 1 AND p.archive = 0 ORDER BY p.title; | V17: Null and zero handling required.
A18: Existing – Retained | B18: 18 | C18: Portfolio Head / Delivery Manager / PM | D18: Medium | E18: Projects | F18: Exception / Diagnostic | G18: Complex | H18: projects_without_members | I18: Which active projects have no allocated users? | J18: Show projects without team members. | K18: List active projects with an empty team. | L18: none | M18: Identify exceptions requiring owner action. | N18: Define active project and active membership. | O18: tbl_projects; tbl_project_users | P18: N/A | Q18: Exception query with joins and threshold filters | R18: High | S18: Orbit KPI Tool with predefined metric logic; Mesh may explain results but must not calculate metrics freely | T18: Not Applicable – Non-Direct Support | V18: Define active project and active membership.
A19: Existing – Reworked with Populated Alternative | B19: 19 | C19: Portfolio Head / Delivery Manager / PM | D19: Medium | E19: Projects | F19: Derived Analysis | G19: Very Complex | H19: project_recent_activity | I19: What project records were updated recently for :project_name? | J19: Show recent project, task, issue, and risk activity for :project_name. | K19: What activity has occurred on :project_name in the last :days days? | L19: project_identifier; days | M19: Support governed management analysis. | N19: The empty project status history table cannot provide an exact status-change log. This replacement provides a recent activity feed from populated update timestamps and risk history. | O19: tbl_projects; tbl_project_tasks; tbl_project_issues; tbl_risk; tbl_risk_history | P19: Available – Reframed Activity View | Q19: Governed multi-table query | R19: High | S19: Orbit KPI Tool with predefined metric logic; Mesh may explain results but must not calculate metrics freely | T19: Pending – Multi-source Activity Query | V19: The empty project status history table cannot provide an exact status-change log. This replacement provides a recent activity feed from populated update timestamps and risk history. Recovered from empty-table dependency.
A20: Existing – Retained | B20: 20 | C20: CEO / Executive / Portfolio Head | D20: High | E20: Projects | F20: Aggregation / Dashboard KPI | G20: Complex | H20: active_project_portfolio | I20: Give me a summary of active projects. | J20: Show active project counts by status and stage. | K20: Summarize the current project portfolio. | L20: current_user_scope | M20: Provide a reusable dashboard metric for monitoring. | N20: Define visibility scope and summary measures. | O20: tbl_projects; status/stage masters | P20: N/A | Q20: Predefined aggregation / grouped KPI query | R20: High | S20: Orbit KPI Tool with predefined metric logic; Mesh may explain results but must not calculate metrics freely | T20: Not Applicable – Non-Direct Support | V20: Define visibility scope and summary measures.
A21: Existing – Retained | B21: 26 | C21: Portfolio Head / Delivery Manager / PM | D21: Medium | E21: Milestones | F21: Derived Analysis | G21: Complex | H21: milestone_task_progress | I21: What is the task completion progress of milestone :milestone_name? | J21: How many milestone tasks are completed? | K21: Show completed versus open tasks for :milestone_name. | L21: milestone_name, project_name | M21: Support governed management analysis. | N21: Define closed task statuses. | O21: mapping; tasks; task status | P21: N/A | Q21: Governed multi-table query | R21: High | S21: Orbit KPI Tool with predefined metric logic; Mesh may explain results but must not calculate metrics freely | T21: Not Applicable – Non-Direct Support | V21: Define closed task statuses.
A22: Existing – Retained | B22: 28 | C22: Portfolio Head / Delivery Manager / PM | D22: Medium | E22: Milestones | F22: Derived Analysis | G22: Complex | H22: milestone_date_slippage | I22: Which milestone dates differ from their mapped task dates? | J22: Show milestones with task schedules outside milestone dates. | K22: List milestone schedule mismatches. | L22: none | M22: Support governed management analysis. | N22: No baseline milestone date exists; this is schedule consistency, not baseline slippage. | O22: milestone tables; mapping | P22: N/A | Q22: Governed multi-table query | R22: High | S22: Orbit KPI Tool with predefined metric logic; Mesh may explain results but must not calculate metrics freely | T22: Not Applicable – Non-Direct Support | V22: No baseline milestone date exists; this is schedule consistency, not baseline slippage.
A23: Existing – Retained | B23: 30 | C23: Portfolio Head / Delivery Manager / PM | D23: Medium | E23: Milestones | F23: Derived Analysis | G23: Very Complex | H23: milestone_owner | I23: Who owns milestone :milestone_name? | J23: Show the owner of :milestone_name. | K23: Who is responsible for :milestone_name? | L23: milestone_name | M23: Support governed management analysis. | N23: No owner column exists on milestone table; may be inferred from task owners only. | O23: milestone tables | P23: N/A | Q23: Governed multi-table query | R23: High | S23: Orbit KPI Tool with predefined metric logic; Mesh may explain results but must not calculate metrics freely | T23: Not Applicable – Non-Direct Support | V23: No owner column exists on milestone table; may be inferred from task owners only.
A24: Existing – Retained | B24: 31 | C24: PM / Team Lead / Employee | D24: Medium | E24: Tasks | F24: Simple Lookup / Filter | G24: Moderate | H24: my_open_tasks | I24: What are my open tasks? | J24: Show tasks assigned to me that are not closed. | K24: List my pending work items. | L24: current_user | M24: Fast operational lookup and drill-down. | N24: Direct lookup/filter; no derived KPI. | O24: tbl_project_task_users; tbl_project_tasks; task status | P24: N/A | Q24: Parameterized lookup/filter | R24: Medium | S24: FAQ/NL2SQL cached template or Orbit aggregation tool; execute on live data | T24: Not Mapped – Business Rule Required | V24: Define open status types and whether task_owner also counts.
A25: Existing – Retained | B25: 32 | C25: PM / Team Lead / Employee | D25: Low | E25: Tasks | F25: Simple Lookup / Filter | G25: Simple | H25: my_tasks_due_today | I25: Which of my tasks are due today? | J25: Show my tasks with today’s due date. | K25: What work is due for me today? | L25: current_user, current_date | M25: Fast operational lookup and drill-down. | N25: Direct lookup/filter; no derived KPI. | O25: task users; tasks | P25: Data Available | Q25: Parameterized lookup/filter | R25: Low | S25: FAQ Tool Call Binding + parameterized SQL; cache intent/SQL, not live response | T25: Mapped – Direct Schema | U25: SELECT t.task_id, t.reference_no, t.title, p.title AS project_title, t.due_date, ts.status_name, t.priority, t.rag, t.percent_complete FROM tbl_project_task_users tu JOIN tbl_project_tasks t ON t.task_id = tu.task_id JOIN tbl_projects p ON p.project_id = t.project_id LEFT JOIN tbl_project_task_status ts ON ts.task_status_id = t.task_status_id WHERE tu.user_id = :current_user_id AND tu.status = 1 AND t.status = 1 AND t.archive = 0 AND DATE(t.due_date) = CURRENT_DATE ORDER BY t.due_date, t.reference_no; | V25: Use organization timezone.
A26: Existing – Retained | B26: 33 | C26: PM / Team Lead / Employee | D26: Medium | E26: Tasks | F26: Exception / Diagnostic | G26: Complex | H26: my_overdue_tasks | I26: Which of my tasks are overdue? | J26: Show my delayed tasks. | K26: List my open tasks past their due date. | L26: current_user, as_of_date | M26: Identify exceptions requiring owner action. | N26: Define open statuses. | O26: task users; tasks; task status | P26: N/A | Q26: Exception query with joins and threshold filters | R26: High | S26: Orbit KPI Tool with predefined metric logic; Mesh may explain results but must not calculate metrics freely | T26: Not Applicable – Non-Direct Support | V26: Define open statuses.
A27: Existing – Retained | B27: 34 | C27: PM / Team Lead / Employee | D27: Low | E27: Tasks | F27: Simple Lookup / Filter | G27: Simple | H27: tasks_assigned_to_user | I27: Show tasks assigned to :employee_name. | J27: List :employee_name’s tasks. | K27: What work is assigned to :employee_name? | L27: employee_name | M27: Fast operational lookup and drill-down. | N27: Direct lookup/filter; no derived KPI. | O27: tbl_project_task_users; tbl_users; tasks | P27: Data Available | Q27: Parameterized lookup/filter | R27: Low | S27: FAQ Tool Call Binding + parameterized SQL; cache intent/SQL, not live response | T27: Mapped – Direct Schema | U27: SELECT u.user_id, CONCAT_WS(' ', u.first_name, u.last_name) AS employee_name, p.title AS project_title, t.task_id, t.reference_no, t.title AS task_title, t.due_date, ts.status_name, tu.allot_percentage FROM tbl_users u JOIN tbl_project_task_users tu ON tu.user_id = u.user_id JOIN tbl_project_tasks t ON t.task_id = tu.task_id JOIN tbl_projects p ON p.project_id = t.project_id LEFT JOIN tbl_project_task_status ts ON ts.task_status_id = t.task_status_id WHERE CONCAT_WS(' ', u.first_name, u.last_name) = :employee_name AND tu.status = 1 AND t.status = 1 AND t.archive = 0 ORDER BY p.title, t.due_date, t.reference_no; | V27: Handle active assignment status.
A28: Existing – Retained | B28: 35 | C28: PM / Team Lead / Employee | D28: Medium | E28: Tasks | F28: Derived Analysis | G28: Complex | H28: project_open_tasks | I28: Show open tasks for :project_name. | J28: List pending tasks under :project_name. | K28: What work remains for :project_name? | L28: project_name | M28: Support governed management analysis. | N28: Define open statuses. | O28: tasks; task status | P28: N/A | Q28: Governed multi-table query | R28: High | S28: Orbit KPI Tool with predefined metric logic; Mesh may explain results but must not calculate metrics freely | T28: Not Applicable – Non-Direct Support | V28: Define open statuses.
A29: Existing – Retained | B29: 36 | C29: PM / Team Lead / Employee | D29: Medium | E29: Tasks | F29: Derived Analysis | G29: Complex | H29: project_closed_tasks | I29: Show completed tasks for :project_name. | J29: List closed tasks under :project_name. | K29: What tasks are finished in :project_name? | L29: project_name | M29: Support governed management analysis. | N29: Define closed status types. | O29: tasks; task status | P29: N/A | Q29: Governed multi-table query | R29: High | S29: Orbit KPI Tool with predefined metric logic; Mesh may explain results but must not calculate metrics freely | T29: Not Applicable – Non-Direct Support | V29: Define closed status types.
A30: Existing – Retained | B30: 37 | C30: PM / Team Lead / Employee | D30: Medium | E30: Tasks | F30: Exception / Diagnostic | G30: Complex | H30: unassigned_tasks | I30: Which tasks are unassigned? | J30: Show tasks with no active assignee. | K30: List unallocated tasks. | L30: project_scope | M30: Identify exceptions requiring owner action. | N30: Confirm whether task_owner is an assignment. | O30: tasks; task users | P30: N/A | Q30: Exception query with joins and threshold filters | R30: High | S30: Orbit KPI Tool with predefined metric logic; Mesh may explain results but must not calculate metrics freely | T30: Not Applicable – Non-Direct Support | V30: Confirm whether task_owner is an assignment.
A31: Existing – Retained | B31: 38 | C31: PM / Team Lead / Employee | D31: Medium | E31: Tasks | F31: Derived Analysis | G31: Complex | H31: high_priority_tasks | I31: Show high-priority open tasks. | J31: List urgent pending tasks. | K31: Which open tasks have high priority? | L31: project_scope | M31: Support governed management analysis. | N31: Confirm priority values. | O31: tasks.priority; task status | P31: N/A | Q31: Governed multi-table query | R31: High | S31: Orbit KPI Tool with predefined metric logic; Mesh may explain results but must not calculate metrics freely | T31: Not Applicable – Non-Direct Support | V31: Confirm priority values.
A32: Existing – Retained | B32: 39 | C32: PM / Team Lead / Employee | D32: Low | E32: Tasks | F32: Simple Lookup / Filter | G32: Simple | H32: red_rag_tasks | I32: Which tasks have a red RAG status? | J32: Show red-health tasks. | K32: List tasks flagged red. | L32: project_scope | M32: Fast operational lookup and drill-down. | N32: Direct lookup/filter; no derived KPI. | O32: tbl_project_tasks.rag | P32: Data Available | Q32: Parameterized lookup/filter | R32: Low | S32: FAQ Tool Call Binding + parameterized SQL; cache intent/SQL, not live response | T32: Mapped – Direct Schema | U32: SELECT t.task_id, t.reference_no, t.title, p.title AS project_title, t.rag, t.due_date, ts.status_name FROM tbl_project_tasks t JOIN tbl_projects p ON p.project_id = t.project_id LEFT JOIN tbl_project_task_status ts ON ts.task_status_id = t.task_status_id WHERE LOWER(t.rag) = 'red' AND t.status = 1 AND t.archive = 0 ORDER BY t.due_date, p.title; | V32: Confirm stored RAG values.
A33: Existing – Retained | B33: 40 | C33: PM / Team Lead / Employee | D33: Low | E33: Tasks | F33: Simple Lookup / Filter | G33: Simple | H33: tasks_due_period | I33: Which tasks are due between :start_date and :end_date? | J33: Show tasks due in the selected period. | K33: List upcoming task deadlines. | L33: start_date, end_date | M33: Fast operational lookup and drill-down. | N33: Direct lookup/filter; no derived KPI. | O33: tbl_project_tasks.due_date | P33: Data Available | Q33: Parameterized lookup/filter | R33: Low | S33: FAQ Tool Call Binding + parameterized SQL; cache intent/SQL, not live response | T33: Mapped – Direct Schema | U33: SELECT t.task_id, t.reference_no, t.title, p.title AS project_title, t.due_date, ts.status_name, t.priority, t.rag FROM tbl_project_tasks t JOIN tbl_projects p ON p.project_id = t.project_id LEFT JOIN tbl_project_task_status ts ON ts.task_status_id = t.task_status_id WHERE t.due_date >= :start_date AND t.due_date < DATE_ADD(:end_date, INTERVAL 1 DAY) AND t.status = 1 AND t.archive = 0 ORDER BY t.due_date, p.title, t.reference_no; | V33: Default visibility scope required.
A34: Existing – Retained | B34: 41 | C34: PM / Team Lead / Employee | D34: Low | E34: Tasks | F34: Simple Lookup / Filter | G34: Simple | H34: task_details | I34: Show details of task :task_reference. | J34: Give me the task summary for :task_reference. | K34: Open task :task_reference. | L34: task_reference | M34: Fast operational lookup and drill-down. | N34: Direct lookup/filter; no derived KPI. | O34: tbl_project_tasks | P34: Data Available | Q34: Parameterized lookup/filter | R34: Low | S34: FAQ Tool Call Binding + parameterized SQL; cache intent/SQL, not live response | T34: Mapped – Direct Schema | U34: SELECT t.task_id, t.reference_no, t.title, t.description, p.project_id, p.title AS project_title, t.task_owner, t.start_date, t.due_date, t.task_status_id, ts.status_name, t.priority, t.rag, t.estimate, t.actual_hours, t.percent_complete, t.update_date FROM tbl_project_tasks t JOIN tbl_projects p ON p.project_id = t.project_id LEFT JOIN tbl_project_task_status ts ON ts.task_status_id = t.task_status_id WHERE t.reference_no = :task_reference AND t.status = 1 AND t.archive = 0; | V34: Prefer reference_no over title.
A35: Existing – Retained | B35: 42 | C35: PM / Team Lead / Employee | D35: Low | E35: Tasks | F35: Simple Lookup / Filter | G35: Simple | H35: subtasks_of_task | I35: Show subtasks of :task_reference. | J35: List child tasks under :task_reference. | K35: What tasks depend hierarchically on :task_reference? | L35: task_reference | M35: Fast operational lookup and drill-down. | N35: Direct lookup/filter; no derived KPI. | O35: tbl_project_tasks.parent_id | P35: Data Available | Q35: Parameterized lookup/filter | R35: Low | S35: FAQ Tool Call Binding + parameterized SQL; cache intent/SQL, not live response | T35: Mapped – Direct Schema | U35: SELECT c.task_id, c.reference_no, c.title, c.start_date, c.due_date, ts.status_name, c.priority, c.rag, c.percent_complete FROM tbl_project_tasks parent JOIN tbl_project_tasks c ON c.parent_id = parent.task_id LEFT JOIN tbl_project_task_status ts ON ts.task_status_id = c.task_status_id WHERE parent.reference_no = :task_reference AND c.status = 1 AND c.archive = 0 ORDER BY c.due_date, c.reference_no; | V35: Hierarchy only; not dependency semantics.
A36: Existing – Retained | B36: 43 | C36: PM / Team Lead / Employee | D36: Low | E36: Tasks | F36: Simple Lookup / Filter | G36: Simple | H36: task_assignees | I36: Who is assigned to task :task_reference? | J36: Show all assignees for :task_reference. | K36: Which users are allocated to :task_reference? | L36: task_reference | M36: Fast operational lookup and drill-down. | N36: Direct lookup/filter; no derived KPI. | O36: tbl_project_task_users; tbl_users | P36: Data Available | Q36: Parameterized lookup/filter | R36: Low | S36: FAQ Tool Call Binding + parameterized SQL; cache intent/SQL, not live response | T36: Mapped – Direct Schema | U36: SELECT u.user_id, CONCAT_WS(' ', u.first_name, u.last_name) AS employee_name, u.email, tu.allot_percentage, tu.post_date AS assigned_on FROM tbl_project_tasks t JOIN tbl_project_task_users tu ON tu.task_id = t.task_id JOIN tbl_users u ON u.user_id = tu.user_id WHERE t.reference_no = :task_reference AND tu.status = 1 ORDER BY employee_name; | V36: Include allot_percentage.
A37: Existing – Retained | B37: 44 | C37: PM / Team Lead / Employee | D37: Low | E37: Tasks | F37: Simple Lookup / Filter | G37: Simple | H37: task_allocation_percentages | I37: Show allocation percentages for task :task_reference. | J37: How is task :task_reference allocated? | K37: List assignees and percentages for :task_reference. | L37: task_reference | M37: Fast operational lookup and drill-down. | N37: Direct lookup/filter; no derived KPI. | O37: tbl_project_task_users.allot_percentage | P37: Data Available | Q37: Parameterized lookup/filter | R37: Low | S37: FAQ Tool Call Binding + parameterized SQL; cache intent/SQL, not live response | T37: Mapped – Direct Schema | U37: SELECT u.user_id, CONCAT_WS(' ', u.first_name, u.last_name) AS employee_name, tu.allot_percentage FROM tbl_project_tasks t JOIN tbl_project_task_users tu ON tu.task_id = t.task_id JOIN tbl_users u ON u.user_id = tu.user_id WHERE t.reference_no = :task_reference AND tu.status = 1 ORDER BY tu.allot_percentage DESC, employee_name; | V37: Confirm whether total may exceed 100%.
A38: Existing – Retained | B38: 45 | C38: PM / Team Lead / Employee | D38: Medium | E38: Tasks | F38: Exception / Diagnostic | G38: Complex | H38: tasks_without_due_date | I38: Which open tasks have no due date? | J38: Show pending tasks missing deadlines. | K38: List tasks without a due date. | L38: project_scope | M38: Identify exceptions requiring owner action. | N38: Define open statuses. | O38: tasks; task status | P38: N/A | Q38: Exception query with joins and threshold filters | R38: High | S38: Orbit KPI Tool with predefined metric logic; Mesh may explain results but must not calculate metrics freely | T38: Not Applicable – Non-Direct Support | V38: Define open statuses.
A39: Existing – Retained | B39: 46 | C39: PM / Team Lead / Employee | D39: Low | E39: Tasks | F39: Simple Lookup / Filter | G39: Simple | H39: task_progress | I39: What is the completion percentage of task :task_reference? | J39: Show progress for :task_reference. | K39: How complete is :task_reference? | L39: task_reference | M39: Fast operational lookup and drill-down. | N39: Direct lookup/filter; no derived KPI. | O39: tbl_project_tasks.percent_complete | P39: Data Available | Q39: Parameterized lookup/filter | R39: Low | S39: FAQ Tool Call Binding + parameterized SQL; cache intent/SQL, not live response | T39: Mapped – Direct Schema | U39: SELECT t.task_id, t.reference_no, t.title, t.percent_complete, ts.status_name, t.update_date FROM tbl_project_tasks t LEFT JOIN tbl_project_task_status ts ON ts.task_status_id = t.task_status_id WHERE t.reference_no = :task_reference AND t.status = 1 AND t.archive = 0; | V39: Validate scale 0–100.
A40: Existing – Retained | B40: 47 | C40: PM / Team Lead / Employee | D40: Medium | E40: Tasks | F40: KPI / Comparative | G40: Complex | H40: task_estimate_vs_actual | I40: Compare estimate and actual hours for task :task_reference. | J40: Show planned versus actual effort for :task_reference. | K40: Is :task_reference over its estimate? | L40: task_reference | M40: Support prioritisation and performance comparison. | N40: Confirm units. | O40: tbl_project_tasks.estimate; actual_hours | P40: Data Available | Q40: Multi-table derived KPI with controlled formula | R40: High | S40: Orbit KPI Tool with predefined metric logic; Mesh may explain results but must not calculate metrics freely | T40: Mapped – Direct Schema | U40: SELECT t.task_id, t.reference_no, t.title, t.estimate AS estimated_hours, t.actual_hours, (t.actual_hours - t.estimate) AS variance_hours, t.estimate_complete AS remaining_estimate_hours FROM tbl_project_tasks t WHERE t.reference_no = :task_reference AND t.status = 1 AND t.archive = 0; | V40: Confirm units.
...

Sheet Executive KPI Questions
A1: Source | B1: Original ID | C1: Audience | D1: Executive Priority | E1: PMS Area | F1: Question Type | G1: Complexity Tag | H1: Canonical Intent | I1: Primary Question | J1: Alternative Phrasing 1 | K1: Alternative Phrasing 2 | L1: Required Parameters | M1: Business Decision / Value | N1: KPI / Derivation Logic | O1: Relevant Populated Tables | P1: Data Readiness | Q1: Query Strategy | R1: LLM Error Risk | S1: Recommended Execution / Cache | T1: Query Mapping Status | U1: SQL Query (Existing or Recovered) | V1: Notes
A2: New – Executive / KPI / Dashboard | C2: CEO / Executive Committee | D2: High | E2: Executive Portfolio | F2: Executive Composite KPI | G2: Very Complex | H2: executive_attention_ranking | I2: Which projects require immediate executive attention, ranked from highest to lowest risk? | J2: Show the top :top_n projects needing leadership intervention. | K2: Create an executive exception list for the portfolio. | L2: as_of_date; top_n; scoring_weights | M2: Focus leadership time on the projects with the largest combined delivery exposure. | N2: Composite score using project RAG, overdue-task ratio, high-severity/open issues, current risk exposure, effort burn, days to end date, and stale-update penalties. | O2: tbl_projects; tbl_project_status; tbl_project_stages; tbl_project_tasks; tbl_project_task_status; tbl_project_issues; tbl_project_issue_status; tbl_risk; tbl_risk_status; tbl_risk_probability; tbl_risk_impact | P2: Available – KPI Rule Required | Q2: Composite multi-table ranking | R2: High | S2: Orbit KPI/Watchlist Tool with fixed formulas; cache intent/query plan, execute against live data; use Mesh only to explain computed results. | T2: Pending – Complex KPI SQL Design
A3: New – Executive / KPI / Dashboard | C3: CEO / Executive Committee / Finance | D3: High | E3: Executive Portfolio | F3: Executive KPI / Dashboard | G3: Complex | H3: deal_weighted_rag_distribution | I3: What percentage of the active portfolio is Red, Amber, or Green when weighted by deal value? | J3: Show deal-value-weighted RAG distribution. | K3: How much portfolio value sits in each RAG category? | L3: as_of_date | M3: Measure financial exposure, not only project counts. | N3: Sum deal_value by RAG and divide by total deal_value for active, non-archived projects. | O3: tbl_projects | P3: Available – KPI Rule Required | Q3: Predefined multi-table KPI / trend aggregation | R3: High | S3: Orbit KPI/Watchlist Tool with fixed formulas; cache intent/query plan, execute against live data; use Mesh only to explain computed results. | T3: Pending – Complex KPI SQL Design
A4: New – Executive / KPI / Dashboard | C4: CEO / Executive Committee / Finance | D4: High | E4: Executive Portfolio | F4: Executive KPI / Dashboard | G4: Complex | H4: deal_value_at_risk | I4: How much deal value is currently at risk in Red and Amber projects? | J4: Show total commercial exposure in unhealthy projects. | K4: What is the value of the portfolio requiring recovery action? | L4: as_of_date; risk_rag_values | M4: Quantify commercial exposure and prioritise recovery investment. | N4: Aggregate deal_value for active projects whose RAG is in configured risk categories; split by PM, client, project type, and stage. | O4: tbl_projects; tbl_clients; tbl_project_types; tbl_project_stages | P4: Available – KPI Rule Required | Q4: Predefined multi-table KPI / trend aggregation | R4: High | S4: Orbit KPI/Watchlist Tool with fixed formulas; cache intent/query plan, execute against live data; use Mesh only to explain computed results. | T4: Pending – Complex KPI SQL Design
A5: New – Executive / KPI / Dashboard | C5: CEO / Delivery Head / Portfolio Head | D5: High | E5: Executive Portfolio | F5: Forecast / Predictive | G5: Very Complex | H5: project_end_date_miss_forecast | I5: Which projects are most likely to miss their committed end dates? | J5: Forecast projects at risk of schedule slippage. | K5: Which projects need intervention to protect their delivery date? | L5: as_of_date; forecast_horizon; scoring_weights | M5: Intervene before delivery dates are missed. | N5: Deterministic risk score using days remaining, overdue/open-task ratio, tasks due after project end, remaining estimated effort, unresolved issue/risk exposure, and update recency. | O5: tbl_projects; tbl_project_status; tbl_project_stages; tbl_project_tasks; tbl_project_task_status; tbl_timesheets; tbl_project_issues; tbl_project_issue_status; tbl_risk; tbl_risk_status | P5: Available – KPI Rule Required | Q5: Deterministic forecast / watchlist scoring | R5: High | S5: Orbit KPI/Watchlist Tool with fixed formulas; cache intent/query plan, execute against live data; use Mesh only to explain computed results. | T5: Pending – Complex KPI SQL Design
A6: New – Executive / KPI / Dashboard | C6: CEO / Delivery Head | D6: High | E6: Executive Portfolio | F6: Executive KPI / Dashboard | G6: Complex | H6: pm_risk_concentration | I6: Which project managers carry the highest concentration of Red or Amber projects? | J6: Rank PMs by unhealthy project count and value. | K6: Which PM portfolios need additional leadership support? | L6: as_of_date; rag_values | M6: Detect concentrated delivery risk and coaching/support needs. | N6: Group active projects by pm_user_id; calculate red/amber project count, percentage, deal value, overdue-task ratio, and issue/risk exposure. | O6: tbl_projects; tbl_users; tbl_project_tasks; tbl_project_issues; tbl_risk | P6: Available – KPI Rule Required | Q6: Predefined multi-table KPI / trend aggregation | R6: High | S6: Orbit KPI/Watchlist Tool with fixed formulas; cache intent/query plan, execute against live data; use Mesh only to explain computed results. | T6: Pending – Complex KPI SQL Design
A7: New – Executive / KPI / Dashboard | C7: CEO / Delivery Head | D7: High | E7: Executive Portfolio | F7: Executive Composite KPI | G7: Very Complex | H7: pm_delivery_performance_scorecard | I7: How are project managers performing across delivery, effort, risk, and issue KPIs? | J7: Show a comparative PM delivery scorecard. | K7: Which PMs consistently deliver healthy projects? | L7: period; scoring_weights; minimum_project_count | M7: Compare performance using consistent evidence rather than narrative judgement. | N7: Composite PM score from project RAG, on-time task rate, average overdue days, effort variance, issue closure rate, risk closure rate, and update freshness. | O7: tbl_projects; tbl_users; tbl_project_tasks; tbl_project_task_status; tbl_timesheets; tbl_project_issues; tbl_project_issue_status; tbl_risk; tbl_risk_status | P7: Available – KPI Rule Required | Q7: Composite multi-table ranking | R7: High | S7: Orbit KPI/Watchlist Tool with fixed formulas; cache intent/query plan, execute against live data; use Mesh only to explain computed results. | T7: Pending – Complex KPI SQL Design
A8: New – Executive / KPI / Dashboard | C8: CEO / Delivery Head / Finance | D8: High | E8: Executive Portfolio | F8: Executive KPI / Dashboard | G8: Complex | H8: portfolio_effort_burn_vs_completion | I8: Which projects are consuming effort faster than they are completing work? | J8: Compare effort burn against delivery completion across the portfolio. | K8: Where is effort consumption outpacing progress? | L8: as_of_date; burn_threshold; completion_method | M8: Identify likely overruns early. | N8: Compare project estimate, total_hours_booked, timesheet hours, and weighted task percent_complete. Flag high burn with low completion. | O8: tbl_projects; tbl_project_tasks; tbl_timesheets | P8: Available – KPI Rule Required | Q8: Predefined multi-table KPI / trend aggregation | R8: High | S8: Orbit KPI/Watchlist Tool with fixed formulas; cache intent/query plan, execute against live data; use Mesh only to explain computed results. | T8: Pending – Complex KPI SQL Design
A9: New – Executive / KPI / Dashboard | C9: CEO / Delivery Head / Finance | D9: High | E9: Executive Portfolio | F9: Exception / KPI | G9: Complex | H9: high_burn_low_completion_projects | I9: Which projects have consumed more than :burn_percent of estimated effort but completed less than :completion_percent of work? | J9: Find high-burn, low-progress projects. | K9: Which projects show the strongest effort-to-progress mismatch? | L9: burn_percent; completion_percent; as_of_date | M9: Create a focused overrun watchlist. | N9: Burn ratio = live logged/booked effort ÷ project estimate. Completion = governed weighted task completion. Filter using configured thresholds. | O9: tbl_projects; tbl_project_tasks; tbl_timesheets | P9: Available – KPI Rule Required | Q9: Predefined multi-table KPI / trend aggregation | R9: High | S9: Orbit KPI/Watchlist Tool with fixed formulas; cache intent/query plan, execute against live data; use Mesh only to explain computed results. | T9: Pending – Complex KPI SQL Design
A10: New – Executive / KPI / Dashboard | C10: CEO / Client Leadership / Delivery Head | D10: High | E10: Executive Portfolio | F10: Executive Composite KPI | G10: Very Complex | H10: client_delivery_exposure | I10: Which clients have the greatest delivery exposure across active projects? | J10: Rank clients by project value, unhealthy RAG, overdue work, risks, and issues. | K10: Where is client relationship risk concentrated? | L10: as_of_date; top_n | M10: Protect strategic client relationships and revenue. | N10: Aggregate project count, deal value, RAG mix, overdue-task ratio, issue severity, and risk exposure by client. | O10: tbl_projects; tbl_clients; tbl_project_tasks; tbl_project_issues; tbl_risk | P10: Available – KPI Rule Required | Q10: Composite multi-table ranking | R10: High | S10: Orbit KPI/Watchlist Tool with fixed formulas; cache intent/query plan, execute against live data; use Mesh only to explain computed results. | T10: Pending – Complex KPI SQL Design
A11: New – Executive / KPI / Dashboard | C11: CEO / Strategy / Delivery Head | D11: High | E11: Executive Portfolio | F11: Executive KPI / Dashboard | G11: Complex | H11: portfolio_segment_performance | I11: Which project types, business models, sources, or categories have the highest delay and overrun rates? | J11: Compare delivery performance across portfolio segments. | K11: Which types of work are structurally underperforming? | L11: period; segment_dimension; minimum_project_count | M11: Improve portfolio strategy, pricing, and delivery model choices. | N11: Group by project_type/project_type_id, business_model, source, or category_type; compare overdue rate, RAG mix, effort variance, issue rate, and risk exposure. | O11: tbl_projects; tbl_project_types; tbl_project_tasks; tbl_timesheets; tbl_project_issues; tbl_risk | P11: Available – KPI Rule Required | Q11: Predefined multi-table KPI / trend aggregation | R11: High | S11: Orbit KPI/Watchlist Tool with fixed formulas; cache intent/query plan, execute against live data; use Mesh only to explain computed results. | T11: Pending – Complex KPI SQL Design
A12: New – Executive / KPI / Dashboard | C12: CEO / Audit / Delivery Head | D12: High | E12: Governance | F12: Executive KPI / Dashboard | G12: Complex | H12: high_value_governance_gaps | I12: Which high-value projects have unresolved governance or audit gaps? | J12: Show projects with pending/review audit status and high deal value. | K12: Where are governance gaps creating material exposure? | L12: deal_value_threshold; as_of_date | M12: Prioritise governance remediation on materially important projects. | N12: Filter projects with audit_status not confirmed or missing/blank lifecycle evidence fields; rank by deal_value and health indicators. | O12: tbl_projects | P12: Available – KPI Rule Required | Q12: Predefined multi-table KPI / trend aggregation | R12: High | S12: Orbit KPI/Watchlist Tool with fixed formulas; cache intent/query plan, execute against live data; use Mesh only to explain computed results. | T12: Pending – Complex KPI SQL Design
A13: New – Executive / KPI / Dashboard | C13: CEO / Delivery Head / PMO | D13: High | E13: Executive Reporting | F13: Exception / KPI | G13: Complex | H13: executive_summary_freshness | I13: Which active projects have stale or missing executive summaries? | J13: Show projects without a recent management update. | K13: Which projects have not provided an executive summary within :days days? | L13: days; as_of_date | M13: Improve management visibility and reporting discipline. | N13: For each active project, compare latest tbl_project_executive_summary.save_date/post_date with as_of_date; rank stale projects by deal value and RAG. | O13: tbl_projects; tbl_project_executive_summary | P13: Available – KPI Rule Required | Q13: Predefined multi-table KPI / trend aggregation | R13: High | S13: Orbit KPI/Watchlist Tool with fixed formulas; cache intent/query plan, execute against live data; use Mesh only to explain computed results. | T13: Pending – Complex KPI SQL Design
... A15: New – Executive / KPI / Dashboard | C15: CEO / Strategy / Delivery Head | D15: High | E15: Executive Portfolio | F15: Trend / Dashboard KPI | G15: Complex | H15: quarterly_portfolio_flow | I15: What is the quarterly trend of projects started, due, completed, and overdue? | J15: Show portfolio inflow and delivery outcomes by quarter. | K15: Is the organisation taking on work faster than it completes it? | L15: start_date; end_date; completion_status_types | M15: Assess portfolio throughput and capacity pressure. | N15: Count projects by start_date, end_date, and configured completed status; calculate overdue projects at each quarter end. | O15: tbl_projects; tbl_project_status | P15: Available – KPI Rule Required | Q15: Predefined multi-table KPI / trend aggregation | R15: High | S15: Orbit KPI/Watchlist Tool with fixed formulas; cache intent/query plan, execute against live data; use Mesh only to explain computed results. | T15: Pending – Complex KPI SQL Design
A16: New – Executive / KPI / Dashboard | C16: CEO / Delivery Head / PMO | D16: High | E16: Executive Portfolio | F16: Exception / KPI | G16: Complex | H16: stage_aging | I16: Which projects have remained in the same delivery stage for too long? | J16: Show stage aging across active projects. | K16: Which projects appear stuck in their current stage? | L16: as_of_date; stage_age_thresholds | M16: Identify stalled projects while clearly exposing the data limitation. | N16: Use project_stage_id and update_date as an available proxy for stage aging; exact stage-entry age requires history and should be labelled approximate. | O16: tbl_projects; tbl_project_stages | P16: Available – KPI Rule Required | Q16: Predefined multi-table KPI / trend aggregation | R16: High | S16: Orbit KPI/Watchlist Tool with fixed formulas; cache intent/query plan, execute against live data; use Mesh only to explain computed results. | T16: Pending – Complex KPI SQL Design | V16: Approximate metric because project stage history is not populated.
A17: New – Executive / KPI / Dashboard | C17: CEO / Delivery Head / PMO | D17: High | E17: Delivery Health | F17: Exception / Diagnostic | G17: Complex | H17: active_projects_without_recent_activity | I17: Which active projects show no recent task, issue, risk, timesheet, or summary activity? | J17: Find active projects that appear dormant. | K17: Which projects have had no operational activity in the last :days days? | L17: days; as_of_date | M17: Detect abandoned, inaccurately active, or poorly maintained projects. | N17: Calculate the latest activity date across project update, task update, issue update, risk update/history, timesheet, and executive summary. | O17: tbl_projects; tbl_project_tasks; tbl_project_issues; tbl_risk; tbl_risk_history; tbl_timesheets; tbl_project_executive_summary | P17: Available – KPI Rule Required | Q17: Predefined multi-table KPI / trend aggregation | R17: High | S17: Orbit KPI/Watchlist Tool with fixed formulas; cache intent/query plan, execute against live data; use Mesh only to explain computed results. | T17: Pending – Complex KPI SQL Design
A18: New – Executive / KPI / Dashboard | C18: Delivery Head / PMO / PM | D18: High | E18: Delivery Health | F18: Exception / Diagnostic | G18: Complex | H18: project_end_before_open_task_due | I18: Which projects have open tasks due after the project end date? | J18: Show project schedules that are internally inconsistent. | K18: Which committed project dates are earlier than their remaining task deadlines? | L18: as_of_date | M18: Identify schedule-plan inconsistencies requiring rebaselining. | N18: Find active/open tasks where task.due_date > project.end_date; summarise count, latest due date, and high-priority exposure by project. | O18: tbl_projects; tbl_project_tasks; tbl_project_task_status | P18: Available – KPI Rule Required | Q18: Predefined multi-table KPI / trend aggregation | R18: High | S18: Orbit KPI/Watchlist Tool with fixed formulas; cache intent/query plan, execute against live data; use Mesh only to explain computed results. | T18: Pending – Complex KPI SQL Design
A19: New – Executive / KPI / Dashboard | C19: Delivery Head / PM / Team Lead | D19: High | E19: Tasks | F19: Executive Composite KPI | G19: Very Complex | H19: critical_bottleneck_tasks | I19: Which incomplete tasks are blocking the largest number of dependent tasks? | J19: Rank overdue bottleneck tasks by downstream dependency count. | K19: What tasks create the greatest delivery bottleneck? | L19: project_identifier; as_of_date; top_n | M19: Focus execution on blockers with the largest downstream impact. | N19: Count tasks whose dependent_task_id points to each incomplete task; combine downstream count, overdue days, priority, RAG, and assignee availability. | O19: tbl_project_tasks; tbl_project_task_status; tbl_project_task_users; tbl_projects | P19: Available – KPI Rule Required | Q19: Composite multi-table ranking | R19: High | S19: Orbit KPI/Watchlist Tool with fixed formulas; cache intent/query plan, execute against live data; use Mesh only to explain computed results. | T19: Pending – Complex KPI SQL Design
A20: New – Executive / KPI / Dashboard | C20: Delivery Head / Portfolio Head / PMO | D20: High | E20: Tasks | F20: Dashboard KPI | G20: Complex | H20: high_priority_backlog_concentration | I20: Which projects contain the highest concentration of open High-priority or Red-RAG tasks? | J20: Rank projects by critical task backlog. | K20: Where is urgent delivery work concentrated? | L20: as_of_date; top_n | M20: Prioritise portfolio recovery actions. | N20: Critical backlog ratio = open High-priority or configured Red-RAG tasks ÷ all open tasks; include count and overdue days. | O20: tbl_projects; tbl_project_tasks; tbl_project_task_status | P20: Available – KPI Rule Required | Q20: Predefined multi-table KPI / trend aggregation | R20: High | S20: Orbit KPI/Watchlist Tool with fixed formulas; cache intent/query plan, execute against live data; use Mesh only to explain computed results. | T20: Pending – Complex KPI SQL Design
A21: New – Executive / KPI / Dashboard | C21: PM / Team Lead / Delivery Head | D21: High | E21: Tasks | F21: Exception / KPI | G21: Complex | H21: tasks_due_soon_low_completion | I21: Which tasks are due within :days days but remain below :completion_percent complete? | J21: Show near-term tasks at risk of missing due dates. | K21: What upcoming work needs immediate action? | L21: days; completion_percent; as_of_date; optional_project | M21: Create a proactive short-term execution watchlist. | N21: Filter open tasks by due-date horizon and percent_complete threshold; rank by priority, RAG, estimate_complete, and dependency impact. | O21: tbl_project_tasks; tbl_project_task_status; tbl_projects | P21: Available – KPI Rule Required | Q21: Predefined multi-table KPI / trend aggregation | R21: High | S21: Orbit KPI/Watchlist Tool with fixed formulas; cache intent/query plan, execute against live data; use Mesh only to explain computed results. | T21: Pending – Complex KPI SQL Design
A22: New – Executive / KPI / Dashboard | C22: Delivery Head / PMO / Finance | D22: High | E22: Tasks | F22: KPI / Comparative | G22: Complex | H22: portfolio_task_estimate_variance | I22: Which projects and tasks have the largest estimate-to-actual effort variance? | J22: Rank task overruns across the portfolio. | K22: Where are estimates least accurate? | L22: period; top_n; actual_effort_source | M22: Improve estimation quality and identify overruns. | N22: Compare task estimate with live timesheet hours; aggregate variance and variance percentage by task, project, PM, type, and client. | O22: tbl_project_tasks; tbl_timesheets; tbl_projects; tbl_users; tbl_clients | P22: Available – KPI Rule Required | Q22: Predefined multi-table KPI / trend aggregation | R22: High | S22: Orbit KPI/Watchlist Tool with fixed formulas; cache intent/query plan, execute against live data; use Mesh only to explain computed results. | T22: Pending – Complex KPI SQL Design
